Workbook

Sheet Reações
A1: Reações da Condessa (passivas e ativas)
A2: Os gatilhos são só ideias: o Conselho (as 3 personas que compõem a Condessa) deve revisar cada um e decidir se aprova, ajusta ou substitui. Estados seguem a ficha (B olhos, C boca, D detalhes, F olhares, V fala, O íris livre, P/H/E camadas). Durações em azul são sugestões.
A3: Regra: nunca menos de 80 reações. O Conselho pode decidir ter mais, ou propor ideias novas na aba Conselho, mas não menos. Passiva = acontece sozinha, sem evento. Ativa = disparada por algo.
A5: Nº | B5: Reação | C5: Tipo | D5: Categoria | E5: Ideia de gatilho | F5: Passo 1 | G5: ms 1 | H5: Passo 2 | I5: ms 2 | J5: Passo 3 | K5: ms 3 | L5: Passo 4 | M5: ms 4 | N5: Duração total (ms) | O5: Asset novo necessário | P5: Decisão do Conselho | Q5: Notas do Conselho
A6: 1 | B6: Respirar e balançar | C6: Passiva | D6: Ambiente | E6: Sempre ligado, em segundo plano | F6: B1 + C1 · respiração do corpo (P6) | G6: 4000 | H6: B1 + C1 · chiquinhas em vento leve (P2/P3/H5/H6) | I6: 3000 | N6: =SUM(G6,I6,K6,M6) | O6: — | P6: Aprovada
A7: 2 | B7: Sacada de olhar | C7: Passiva | D7: Ambiente | E7: Aleatório, a cada poucos segundos | F7: B1 + C1 | G7: 2500 | H7: O1: íris desvia pro lado | I7: 700 | J7: O1: íris volta pra câmera | K7: 400 | N7: =SUM(G7,I7,K7,M7) | O7: — | P7: Aprovada
A8: 3 | B8: Piscada dupla | C8: Passiva | D8: Ambiente | E8: Aleatório, raro | F8: B2 | G8: 40 | H8: B3 | I8: 80 | J8: B1 | K8: 120 | L8: B2 → B3 → B1 | M8: 200 | N8: =SUM(G8,I8,K8,M8) | O8: — | P8: Aprovada
A9: 4 | B9: Piscada lenta de gato | C9: Passiva | D9: Ambiente | E9: Aleatório quando está calma ou de bom humor | F9: B2 | G9: 150 | H9: B3 + C5 | I9: 500 | J9: B2 | K9: 150 | L9: B1 + C1 | M9: 200 | N9: =SUM(G9,I9,K9,M9) | O9: — | P9: Aprovada
A10: 5 | B10: Seguir o cursor | C10: Passiva | D10: Ambiente | E10: Mouse em movimento pela tela | F10: O1: íris acompanha o cursor em sacadas curtas | G10: 2000 | N10: =SUM(G10,I10,K10,M10) | O10: — | P10: Ajustar gatilho | Q10: sacada curta para o card que acabou de mudar (faixa, manchete, FPS)
A11: 6 | B11: Observando o HUD | C11: Passiva | D11: Ambiente | E11: Aleatório, como quem confere os cards | F11: F1 (lado do MAGI) | G11: 900 | H11: F4 (Now playing) | I11: 900 | J11: F5 (Rádio / Claude Code) | K11: 900 | L11: F3 (FPS / rede) | M11: 900 | N11: =SUM(G11,I11,K11,M11) | O11: — | P11: Aprovada
A12: 7 | B12: Micro sorriso de canto | C12: Passiva | D12: Ambiente | E12: Aleatório | F12: B1 + C10 | G12: 1500 | N12: =SUM(G12,I12,K12,M12) | O12: — | P12: Aprovada
A13: 8 | B13: Beicinho passageiro | C13: Passiva | D13: Ambiente | E13: Aleatório | F13: B1 + C9 | G13: 1200 | N13: =SUM(G13,I13,K13,M13) | O13: — | P13: Aprovada
A14: 9 | B14: Suspiro leve | C14: Passiva | D14: Ambiente | E14: Aleatório | F14: B2 + C4 · respiração funda | G14: 900 | H14: B1 + C1 | I14: 500 | N14: =SUM(G14,I14,K14,M14) | O14: — | P14: Aprovada
A15: 10 | B15: Cantarolando sozinha | C15: Passiva | D15: Ambiente | E15: Aleatório e raro, sem música tocando | F15: B2 + C13 | G15: 1200 | H15: B1 + C1 + D6 (uma nota) | I15: 1000 | N15: =SUM(G15,I15,K15,M15) | O15: — | P15: Aprovada
A16: 11 | B16: Rindo sozinha | C16: Passiva | D16: Ambiente | E16: Aleatório e raro (lembrou de algo) | F16: B1 + C5 | G16: 800 | H16: B5 + C6 | I16: 1200 | J16: B4 + C5 | K16: 800 | N16: =SUM(G16,I16,K16,M16) | O16: — | P16: Aprovada
A17: 12 | B17: Corando sozinha | C17: Passiva | D17: Ambiente | E17: Aleatório e muito raro | F17: F3 + C1 | G17: 600 | H17: B4 + C5 + D1 | I17: 1800 | J17: B1 + C1 | K17: 600 | N17: =SUM(G17,I17,K17,M17) | O17: — | P17: Aprovada
A18: 13 | B18: Falando sozinha em silêncio | C18: Passiva | D18: Ambiente | E18: Aleatório, sem voz | F18: B13 + V1 | G18: 300 | H18: B13 + V5 | I18: 150 | J18: B13 + V2 | K18: 250 | L18: B13 + V3 | M18: 300 | N18: =SUM(G18,I18,K18,M18) | O18: — | P18: Aprovada
A19: 14 | B19: Brilho da presilha | C19: Passiva | D19: Ambiente | E19: Quando a cabeça mexe ou aleatório | F19: B1 + C1 + H4 (brilho cruza a presilha) | G19: 900 | N19: =SUM(G19,I19,K19,M19) | O19: — | P19: Aprovada
A20: 15 | B20: Encarando | C20: Passiva | D20: Ambiente | E20: Mouse parado sobre ela por ~10 s | F20: B1 + C1 · olhar fixo na câmera (O1) | G20: 3000 | H20: B3 · piscada lenta | I20: 500 | J20: B1 + C10 | K20: 1000 | N20: =SUM(G20,I20,K20,M20) | O20: — | P20: Aprovada | Q20: Aprovada condicionada ao sinal A (retrato): mouse parado ≥10 s. Fora do código até o sinal existir.
A21: 16 | B21: Soprando a franja | C21: Passiva | D21: Ambiente | E21: Tédio leve ou aleatório | F21: B13 + C1 | G21: 800 | H21: B2 + V4 + H3 (franja balança) | I21: 700 | J21: B1 + C1 | K21: 500 | N21: =SUM(G21,I21,K21,M21) | O21: — | P21: Aprovada
A22: 17 | B22: Bocejo | C22: Passiva | D22: Tédio e sono | E22: ~2 min sem interação | F22: B14 + C1 | G22: 800 | H22: B15 + C4 (bocejo) | I22: 1200 | J22: B14 + C1 | K22: 600 | L22: B1 + C1 | M22: 400 | N22: =SUM(G22,I22,K22,M22) | O22: — | P22: Ajustar gatilho | Q22: 10 min com Magui, Claude, música e jogo parados
A23: 18 | B23: Cochilo | C23: Passiva | D23: Tédio e sono | E23: ~5 min sem interação | F23: B14 + C1 | G23: 1500 | H23: B15 + C1 + D3 (zz) · cabeça cai | I23: 3000 | N23: =SUM(G23,I23,K23,M23) | O23: — | P23: Ajustar gatilho | Q23: mesmas condições do 17 por 25 min (fundo sleepy)
A24: 19 | B24: Cabeça pesada | C24: Passiva | D24: Tédio e sono | E24: Sessão muito longa, de madrugada | F24: B14 + C1 | G24: 1500 | H24: B15 + C1 · cabeça cai | I24: 500 | J24: B9 + C7 · desperta | K24: 400 | L24: B14 + C1 | M24: 800 | N24: =SUM(G24,I24,K24,M24) | O24: — | P24: Aprovada | Q24: nunca com jogo, Claude rodando ou música nota ≥1
A25: 20 | B25: Acordando em sobressalto | C25: Ativa | D25: Tédio e sono | E25: Você volta enquanto ela cochilava | F25: B9 + C7 + D5 | G25: 500 | H25: B2 + C9 | I25: 500 | J25: B1 + C5 | K25: 600 | N25: =SUM(G25,I25,K25,M25) | O25: — | P25: Ajustar gatilho | Q25: estava no 18 e chega qualquer evento real; fura cota
A26: 21 | B26: Fone em repouso | C26: Passiva | D26: Música | E26: Sem música tocando | F26: B1 + C1 + E3 (fone no pescoço) | G26: 3000 | N26: =SUM(G26,I26,K26,M26) | O26: E3 | P26: Aprovada
A27: 22 | B27: Ajeitando o fone | C27: Passiva | D27: Música | E27: Música tocando, de tempos em tempos | F27: B5 + C5 + E2 | G27: 900 | H27: B1 + E2 balança (ou P11 mão no fone) | I27: 500 | N27: =SUM(G27,I27,K27,M27) | O27: P11 (opcional) | P27: Aprovada
A28: 23 | B28: Cabeça no ritmo | C28: Passiva | D28: Música | E28: Qualquer música tocando | F28: B2 + C1 + E2 · balanço lento | G28: 1500 | H28: B1 + C5 + E2 | I28: 1500 | N28: =SUM(G28,I28,K28,M28) | O28: — | P28: Aprovada
A29: 24 | B29: Colocando o fone | C29: Ativa | D29: Música | E29: Música começa a tocar | F29: F4 (Now playing) | G29: 600 | H29: B2 + C1 + E2 desce até a cabeça | I29: 400 | J29: B5 + C13 + D6 + E2 · cabeça no ritmo | K29: 2000 | N29: =SUM(G29,I29,K29,M29) | O29: — | P29: Ajustar gatilho | Q29: música começa a tocar; cooldown 3 min
A30: 25 | B30: Tirando o fone | C30: Ativa | D30: Música | E30: Música para ou ela vai falar com você | F30: B9 + C7 · E2 sai | G30: 500 | H30: B1 + C1 | I30: 600 | N30: =SUM(G30,I30,K30,M30) | O30: — | P30: Ajustar gatilho | Q30: Spotify tocando sim→não
A31: 26 | B31: Refrão chegou | C31: Ativa | D31: Música | E31: Pico de volume ou refrão detectado | F31: B4 + C5 + E2 | G31: 500 | H31: B5 + C6 + D9 + D6 · cabeça balança forte | I31: 2500 | N31: =SUM(G31,I31,K31,M31) | O31: — | P31: Ajustar gatilho | Q31: nota 2 passa de 60 s sem pulo, 1×/faixa; sem texto de 'refrão'; pico RMS vira variante condicionada
A32: 27 | B32: Cantando junto | C32: Ativa | D32: Música | E32: Música que ela conhece | F32: B5 + V1 | G32: 400 | H32: B5 + V2 | I32: 300 | J32: B5 + V3 | K32: 400 | L32: B4 + V5 | M32: 300 | N32: =SUM(G32,I32,K32,M32) | O32: — | P32: Ajustar gatilho | Q32: nota 2 ou ≥5 plays; após 40 s; 1×/faixa
A33: 28 | B33: Música repetida | C33: Ativa | D33: Música | E33: Mesma faixa tocando pela 3ª vez | F33: B7 + C12 | G33: 1000 | H33: F7 + C11 | I33: 1200 | N33: =SUM(G33,I33,K33,M33) | O33: — | P33: Ajustar gatilho | Q33: 3ª vez da faixa no dia; Ado variante happy, nunca perde
A34: 29 | B34: Música triste | C34: Ativa | D34: Música | E34: Faixa lenta ou melancólica | F34: B10 + C9 + E2 | G34: 1200 | H34: F7 + C1 + D7 (lágrima) | I34: 2500 | N34: =SUM(G34,I34,K34,M34) | O34: — | P34: Ajustar gatilho | Q34: lista melancolica/título (nocturne, requiem, sad…); D7 só 22h–04h, ≤1/dia
A35: 30 | B35: Música dançante | C35: Ativa | D35: Música | E35: Faixa agitada | F35: B4 + C10 + E2 · corpo balança | G35: 1500 | H35: B5 + C6 + D6 · chiquinhas balançam | I35: 2000 | N35: =SUM(G35,I35,K35,M35) | O35: — | P35: Ajustar gatilho | Q35: gênero da lista danca do toml, nota ≥1
A36: 31 | B36: Volume alto demais | C36: Ativa | D36: Música | E36: Volume sobe de repente | F36: B9 + C4 + D2 · E2 sai | G36: 600 | H36: B7 + C9 | I36: 700 | N36: =SUM(G36,I36,K36,M36) | O36: — | P36: Aprovada | Q36: Aprovada condicionada ao sinal D (volume PipeWire): salto ≥20 pp em ≤2 s. Fora do código até o sinal existir.
A37: 32 | B37: Fim do álbum | C37: Ativa | D37: Música | E37: Playlist ou álbum termina | F37: B5 + C5 + E2 | G37: 1200 | H37: B2 + C1 · sentindo falta | I37: 1000 | J37: B1 + C1 · E2 sai | K37: 800 | N37: =SUM(G37,I37,K37,M37) | O37: — | P37: Ajustar gatilho | Q37: renomear 'Acabou a fila': parou no fim e nada começou em 10 s
A38: 33 | B38: Descobriu música que amou | C38: Ativa | D38: Música | E38: Artista novo com nota alta | F38: B13 + C7 | G38: 800 | H38: B9 + C7 + D5 | I38: 500 | J38: B5 + C13 + D9 + D6 | K38: 2500 | N38: =SUM(G38,I38,K38,M38) | O38: — | P38: Ajustar gatilho | Q38: artista sem play anterior e nota ≥1 (variante de music_new)
A39: 34 | B39: Temperatura escalando | C39: Ativa | D39: Sistema | E39: CPU/GPU esquentando | F39: F1 + C8 + D2 | G39: 3000 | H39: B9 + C7 + D5 + D2 | I39: 1500 | N39: =SUM(G39,I39,K39,M39) | O39: — | P39: Aprovada | Q39: rosto do `hot` existente (variante)
A40: 35 | B40: Alívio térmico | C40: Ativa | D40: Sistema | E40: Temperatura volta ao normal | F40: B3 + C4 · suspiro (D2 some) | G40: 900 | H40: B4 + C5 | I40: 1500 | N40: =SUM(G40,I40,K40,M40) | O40: — | P40: Aprovada | Q40: variante do `hot`; histerese
A41: 36 | B41: FPS despencando | C41: Ativa | D41: Sistema | E41: FPS abaixo do limite por alguns segundos | F41: F3 + C11 | G41: 1500 | H41: B6 + C8 + D2 | I41: 1500 | N41: =SUM(G41,I41,K41,M41) | O41: — | P41: Aprovada | Q41: rosto do `fps_drop`
...

Sheet Resumo
A1: Resumo
A2: Tudo calculado a partir das abas Reações e Conselho; muda sozinho conforme o Conselho decide.
A4: Piso de reações
A5: Reações listadas (aba Reações) | B5: =COUNTA(Reações!$B$6:$B$300)
A6: Ideias novas do Conselho | B6: =COUNTA(Conselho!$B$10:$B$39)
A7: Total de reações | B7: =B5+B6
A8: Mínimo exigido | B8: 80 | C8: Piso definido por você (80).
A9: Situação | B9: =IF(B7>=B8,"OK: piso cumprido","ABAIXO DO MÍNIMO")
A11: Por tipo
A12: Tipo | B12: Reações | C12: Duração média (ms)
A13: Passiva | B13: =COUNTIF(Reações!$C$6:$C$300,A13) | C13: =IFERROR(AVERAGEIF(Reações!$C$6:$C$300,A13,Reações!$N$6:$N$300),"")
A14: Ativa | B14: =COUNTIF(Reações!$C$6:$C$300,A14) | C14: =IFERROR(AVERAGEIF(Reações!$C$6:$C$300,A14,Reações!$N$6:$N$300),"")
A16: Por categoria
A17: Categoria | B17: Reações | C17: Duração média (ms)
A18: Ambiente | B18: =COUNTIF(Reações!$D$6:$D$300,A18) | C18: =IFERROR(AVERAGEIF(Reações!$D$6:$D$300,A18,Reações!$N$6:$N$300),"")
A19: Tédio e sono | B19: =COUNTIF(Reações!$D$6:$D$300,A19) | C19: =IFERROR(AVERAGEIF(Reações!$D$6:$D$300,A19,Reações!$N$6:$N$300),"")
A20: Música | B20: =COUNTIF(Reações!$D$6:$D$300,A20) | C20: =IFERROR(AVERAGEIF(Reações!$D$6:$D$300,A20,Reações!$N$6:$N$300),"")
A21: Sistema | B21: =COUNTIF(Reações!$D$6:$D$300,A21) | C21: =IFERROR(AVERAGEIF(Reações!$D$6:$D$300,A21,Reações!$N$6:$N$300),"")
A22: Claude Code | B22: =COUNTIF(Reações!$D$6:$D$300,A22) | C22: =IFERROR(AVERAGEIF(Reações!$D$6:$D$300,A22,Reações!$N$6:$N$300),"")
A23: Tempo | B23: =COUNTIF(Reações!$D$6:$D$300,A23) | C23: =IFERROR(AVERAGEIF(Reações!$D$6:$D$300,A23,Reações!$N$6:$N$300),"")
A24: Interação | B24: =COUNTIF(Reações!$D$6:$D$300,A24) | C24: =IFERROR(AVERAGEIF(Reações!$D$6:$D$300,A24,Reações!$N$6:$N$300),"")
A25: Rádio Ayanami | B25: =COUNTIF(Reações!$D$6:$D$300,A25) | C25: =IFERROR(AVERAGEIF(Reações!$D$6:$D$300,A25,Reações!$N$6:$N$300),"")
A26: Conversa e personalidade | B26: =COUNTIF(Reações!$D$6:$D$300,A26) | C26: =IFERROR(AVERAGEIF(Reações!$D$6:$D$300,A26,Reações!$N$6:$N$300),"")
A27: Total | B27: =SUM(B18:B26) | C27: =IFERROR(AVERAGE(Reações!$N$6:$N$300),"")
A29: Decisão do Conselho
A30: Decisão | B30: Reações
A31: Pendente | B31: =COUNTIF(Reações!$P$6:$P$300,A31)
A32: Aprovada | B32: =COUNTIF(Reações!$P$6:$P$300,A32)
A33: Ajustar gatilho | B33: =COUNTIF(Reações!$P$6:$P$300,A33)
A34: Substituir | B34: =COUNTIF(Reações!$P$6:$P$300,A34)
A36: Dependem de asset novo
A37: Reações que precisam de asset novo | B37: =SUMPRODUCT((Reações!$O$6:$O$300<>"—")*(Reações!$O$6:$O$300<>""))
A38: Reações que usam só o que já existe | B38: =B5-B37

Sheet Conselho
A1: Conselho: decisões sobre as reações
A3: O que o Conselho decide | B3: Para cada reação da aba Reações: marcar a Decisão (Aprovada, Ajustar gatilho ou Substituir) e anotar o motivo. Os gatilhos são só ideias, não valem até o Conselho aprovar.
A4: Mais ou ideias novas | B4: O Conselho também decide se vale ter mais reações do que as que estão listadas, e propõe ideias novas na tabela abaixo.
A5: Piso de 80 | B5: O total nunca pode ficar abaixo de 80. Marcar "Substituir" não tira a reação da contagem: a substituta deve ser proposta na tabela abaixo. O Resumo mostra se o piso está cumprido.
A6: Personagem e gosto | B6: A personalidade e o gosto da Condessa vivem em persona/condessa.md (decidido pelo Conselho). As expressões aqui devem respeitar esse arquivo; se uma reação não combina com ela, trocar.
A7: Exemplo de ideia nova | B7: "Espirro do HUD" | Passiva | Ambiente | Aleatório e muito raro | B3 + V2 → B9 + C7 · fungada. (É só um exemplo de formato; não conta no total.)
A8: Ideias novas propostas pelo Conselho (cada linha preenchida na coluna Reação nova entra no total)
A9: Nº | B9: Reação nova | C9: Tipo | D9: Categoria | E9: Ideia de gatilho | F9: Sequência sugerida | G9: Quem propôs / nota
A10: 1 | B10: Fim de expediente | C10: Ativa | D10: Tempo | E10: Claude de ≥1 sessão para 0 após ≥2 h, depois das 18h | F10: B4+C5+P9 (1200) → B2+C5 (800) | G10: Kurisu · substitui o 49
A11: 2 | B11: Boa noite | C11: Ativa | D11: Tempo | E11: 0h–4h, música parou e Claude parado ≥10 min | F11: B1+C5 (800) → B14+C1 (700) → B15+C1 (1200) | G11: Aqua · substitui o 49
A12: 3 | B12: Tontura de pulos | C12: Ativa | D12: Música | E12: 5 pulos em 60 s (escala do skips) | F12: B9+C7+D2 (600) → B10+C9 (1200) | G12: Kurisu · substitui o 68
A13: 4 | B13: Vergonha de FPS | C13: Ativa | D13: Sistema | E13: fps_drop pela 3ª vez na mesma sessão de jogo | F13: F3+C11 (1200) → B6+C8+D2 (1500) → B7+C12 (1000) | G13: Asuka
A14: 5 | B14: Sistema sufocando | C14: Ativa | D14: Sistema | E14: RAM ≥90% ou swap +1 GB em 60 s | F14: B9+C7+D5 (600) → B6+C8+D2 (1500) | G14: Kurisu
A15: 6 | B15: Partida sem tropeço | C15: Ativa | D15: Sistema | E15: jogo ≥30 min sem fps_drop, 1×/sessão | F15: B9+C7 (400) → B5+C6+D9 (2500) | G15: Aqua + Asuka (funde Recorde de FPS)
A16: 7 | B16: Favorita do Dia em campo | C16: Ativa | D16: Música | E16: toca o artista sorteado como Favorita do Dia | F16: B1+C1 (200) → B4+C5+D9 (1200) | G16: Kurisu + Aqua
A17: 8 | B17: Duelo com a Ado | C17: Ativa | D17: Música | E17: faixa da Ado começa (nunca D1 nem love) | F17: B7+C12 (800) → B6+C8 (1200) → B4+C10 (1200) | G17: Asuka + Aqua
A18: 9 | B18: A Conta Anônima | C18: Ativa | D18: Música | E18: vocaloid ou Kenshi Yonezu/hachi tocando há 40 s | F18: B5+V1 (300) → B5+V2 (300) → F1+C1+D2 (1200) → B4+C10 (800) | G18: Kurisu + Aqua
A19: 10 | B19: Diva contra Diva | C19: Ativa | D19: Música | E19: Lady Gaga começa a tocar | F19: B7+C12 (1000) → B4+C10 (1200) | G19: Kurisu + Aqua
A20: 11 | B20: Tema água | C20: Ativa | D20: Música | E20: título com palavra de água (Odisseia 6) | F20: B13+C7 (800) → B4+C6+D6 (1800) | G20: Kurisu + Aqua
A21: 12 | B21: Calada pelo Chopin | C21: Ativa | D21: Música | E21: 0h–4h, Chopin ou Marika Takeuchi (variante do 29) | F21: B3+C5 (3000) → B2+C1 (600) | G21: Aqua
... A29: 20 | B29: Braços cruzados | C29: Passiva | D29: Ambiente | E29: aleatório raro com fundo stress/focus; 1×/dia (condicionada à arte P13) | F29: B7+C9+P13 (2000) → B1+C1 (600) | G29: Asuka
A30: 21
A31: 22
A32: 23
A33: 24
A34: 25
A35: 26
A36: 27
A37: 28
A38: 29
A39: 30

Sheet Humor
A1: Humor persistente
A2: Variável que dura minutos e inclina quais reações passivas aparecem. Peso (azul) é um ponto de partida para ajustar, não um valor definido. O Conselho pode rever os fatores.
A4: Fator | B4: Condição | C4: Efeito nas reações passivas | D4: Reações favorecidas | E4: Peso inicial (0–10)
A5: Sessão longa | B5: Sessão de 2 h ou mais | C5: Mais sonolência e bocejos | D5: Bocejo, Cabeça pesada, Cochilo | E5: 6
A6: Música tocando (qualquer) | B6: Qualquer música em reprodução | C6: Fone na cabeça, cabeça balançando; tira só pra falar com você | D6: Cabeça no ritmo, Ajeitando o fone, Cantarolando sozinha | E6: 7
A7: Música que ela gosta | B7: Música com nota ≥ 1 no gosto | C7: Mais sorrisos de canto, mais animação | D7: Micro sorriso de canto, Piscada lenta de gato, Rindo sozinha | E7: 7
A8: PC com problema | B8: CPU/GPU quente, FPS caindo, travou | C8: Mais preocupação e impaciência | D8: Suspiro leve, Beicinho passageiro, Observando o HUD | E8: 7
A9: Manhã | B9: Primeiro uso do dia | C9: "Bom dia": acorda e sorri | D9: Piscada lenta de gato, Micro sorriso de canto | E9: 3
A10: Madrugada | B10: Uso de madrugada | C10: Sonolenta, bocejos | D10: Bocejo, Cabeça pesada, Suspiro leve | E10: 7
A11: Pedro mal | B11: Humor do Pedro 0–1 (núcleo) | C11: Só carinho; bloqueia a zoeira | D11: Piscada lenta de gato, Respirar e balançar | E11: 9
A12: Desempenho em jogo | B12: Jogo aberto + FPS estável ≥5 min | C12: Passivas pela metade | D12: Micro sorriso de canto, Modo chefe, Brilho da presilha | E12: 7
A13: Música que ela odeia | B13: Nota −1 tocando | C13: Emburrada leve | D13: Beicinho passageiro, Suspiro leve, Soprando a franja | E13: 5
A14: Vitória recente | B14: 10 min após 35, 37, 39, 53, 75, faxina | C14: Mais sorrisos | D14: Micro sorriso de canto, Rindo sozinha | E14: 6
A15: Silêncio longo | B15: Sem música e Claude parado ≥30 min | C15: Tédio | D15: Suspiro leve, Beicinho passageiro, Soprando a franja | E15: 4
A16: Favorita do Dia tocando | B16: Artista da Favorita do Dia tocando | C16: Animação; nunca corar | D16: Cabeça no ritmo, Micro sorriso de canto, Cantarolando sozinha | E16: 8

Sheet Assets novos
A1: Assets novos que mais rendem
A2: IDs sugeridos continuam a numeração da ficha (B1–B15, P1–P8, E1–E2). Prompts seguem o padrão de inpainting da ficha. A coluna "Reações que usam" aponta pra aba Reações. Marque "Feita?" conforme for entregando.
A4: Prioridade | B4: ID sugerido | C4: Nome | D4: Região que muda | E4: O que desenhar | F4: Prompt (inpainting) | G4: Usos | H4: Reações que usam | I4: Feita?
A5: 1 | B5: B16 | C5: Piscadinha (wink) | D5: olhos + sobrancelhas | E5: Olho esquerdo fechado em ^, olho direito aberto e sorrindo, sobrancelhas felizes. | F5: same character, same pose, keep the solid #00FF00 green background, edit ONLY the eyes: winking, left eye closed in a happy ^ curve, right eye open and smiling, eyebrows raised and arched | G5: zoeira, flerte, "deixa comigo" | H5: Provocação com piscadinha | I5: não
A6: 1 | B6: E3 | C6: Fone no pescoço | D6: fone / cabeça | E6: Fone de ouvido apoiado ao redor do pescoço, cabeça sem fone. Estado de repouso sem música. | F6: same character, same pose, keep the solid #00FF00 green background, edit ONLY: headphones resting around her neck, no headphones on the head | G6: repouso sem música; troca com o E2 quando a música começa ou para | H6: Fone em repouso | I6: não
A7: 2 | B7: P9 | C7: Braço acenando | D7: braço (troca P7/P8) | E7: Braço levantado em aceno amigável, mão aberta. | F7: same character, same pose, keep the solid #00FF00 green background, edit ONLY the arm on the right side of the image: arm raised in a friendly wave, open hand | G7: "oi", "tchau" | H7: Bom dia, PC desligando (opcional) | I7: não
A8: 2 | B8: P10 | C8: Mão no queixo | D8: braço (troca P7/P8) | E8: Mão levantada até o queixo, pose de quem pensa. | F8: same character, same pose, keep the solid #00FF00 green background, edit ONLY the arm on the right side of the image: hand raised to the chin in a thinking pose | G8: pensando, ideia | H8: Ideia!, Indecisa (opcional) | I8: não
A9: 3 | B9: P11 | C9: Mão no fone | D9: braço (troca P7/P8) | E9: Mão levantada tocando o fone na orelha, ajeitando ou ouvindo com atenção. | F9: same character, same pose, headphones on her head, keep the solid #00FF00 green background, edit ONLY the arm on the right side of the image: hand raised touching the headphone on her ear | G9: ajeitando o fone, ouvindo atento | H9: Ajeitando o fone (opcional) | I9: não
A10: 2 | B10: B17 | C10: Olhos felizes meio | D10: olhos + sobrancelhas | E10: B4 com as pálpebras na metade: piscada suave do feliz (hoje vai direto pro fechado B5). | F10: same character, same pose, edit only the eyes: smiling happy eyes, eyelids half closed mid-blink, eyebrows raised and arched | G10: piscada do feliz | H10: — | I10: não
A11: 0 | B11: D1/D2/D6/D8 | C11: Rubor, suor, notas, veia | D11: detalhes | E11: Arte dos detalhes hoje desenhados em código | G11: dezenas de sequências | H11: várias | I11: não
A12: 1 | B12: D7 | C12: Lágrima | D12: detalhes | E12: Lágrima no canto do olho | G12: 29, 76 (madrugada) | H12: Música triste, Rindo | I12: não
A13: 2 | B13: P12 | C13: Punho cerrado | D13: braço (troca P7/P8) | E13: Mão fechada em punho, orgulho | G13: Duelo com a Ado, Partida sem tropeço | H13: — | I13: não
A14: 2 | B14: P13 | C14: Braços cruzados | D14: braços | E14: Braços cruzados na frente do corpo | G14: cobrança, orgulho | H14: Braços cruzados | I14: não
